{"name": "test_logout", "status": "failed", "statusDetails": {"message": "AssertionError: assert False == True", "trace": "def test_logout():\n        print(\"Running the second test case\")\n        print(\"Logging out\")\n        # Added failure line to fail the TC\n        var = 2 == 5\n>       assert var == True\nE       assert False == True\n\npytestCases\\test_login.py:28: AssertionError"}, "start": 1711523361870, "stop": 1711523361870, "uuid": "6159364c-16bf-4cd2-9726-bfa327f9a4fa", "historyId": "5a1ccdc7b210fad473a92d6e8440254c", "testCaseId": "5a1ccdc7b210fad473a92d6e8440254c", "fullName": "pytestCases.test_login#test_logout", "labels": [{"name": "parentSuite", "value": "pytestCases"}, {"name": "suite", "value": "test_login"}, {"name": "host", "value": "Thrinath"}, {"name": "thread", "value": "3648-MainThread"}, {"name": "framework", "value": "pytest"}, {"name": "language", "value": "cpython3"}, {"name": "package", "value": "pytestCases.test_login"}]}